<?xml version="1.0" encoding="UTF-8"?>
<testng-results skipped="0" failed="4" ignored="2" total="8" passed="2">
  <reporter-output>
  </reporter-output>
  <suite name="Suite" duration-ms="99" started-at="2019-02-03T13:37:21Z" finished-at="2019-02-03T13:37:21Z">
    <groups>
    </groups>
    <test name="Test" duration-ms="99" started-at="2019-02-03T13:37:21Z" finished-at="2019-02-03T13:37:21Z">
      <class name="com.withTestNG.Test1">
        <test-method status="PASS" signature="setup()[pri:0, instance:com.withTestNG.Test1@528931cf]" name="setup" is-config="true" duration-ms="257" started-at="2019-02-03T13:37:20Z" finished-at="2019-02-03T13:37:21Z">
          <reporter-output>
          </reporter-output>
        </test-method> <!-- setup -->
        <test-method status="PASS" signature="funcTest1()[pri:0, instance:com.withTestNG.Test1@528931cf]" name="funcTest1" duration-ms="13" started-at="2019-02-03T13:37:21Z" finished-at="2019-02-03T13:37:21Z">
          <reporter-output>
          </reporter-output>
        </test-method> <!-- funcTest1 -->
        <test-method status="PASS" signature="getResult(org.testng.ITestResult)[pri:0, instance:com.withTestNG.Test1@528931cf]" name="getResult" is-config="true" duration-ms="14" started-at="2019-02-03T13:37:21Z" finished-at="2019-02-03T13:37:21Z">
          <params>
            <param index="0">
              <value>
                <![CDATA[[TestResult name=funcTest1 status=SUCCESS method=Test1.funcTest1()[pri:0, instance:com.withTestNG.Test1@528931cf] output={null}]]]>
              </value>
            </param>
          </params>
          <reporter-output>
          </reporter-output>
        </test-method> <!-- getResult -->
        <test-method status="FAIL" signature="funcTest2()[pri:0, instance:com.withTestNG.Test1@528931cf]" name="funcTest2" duration-ms="4" started-at="2019-02-03T13:37:21Z" finished-at="2019-02-03T13:37:21Z">
          <exception class="java.lang.AssertionError">
            <message>
              <![CDATA[expected [Yogi] but found [Yogesh]]]>
            </message>
            <full-stacktrace>
              <![CDATA[java.lang.AssertionError: expected [Yogi] but found [Yogesh]
at org.testng.Assert.fail(Assert.java:96)
at org.testng.Assert.failNotEquals(Assert.java:776)
at org.testng.Assert.assertEqualsImpl(Assert.java:137)
at org.testng.Assert.assertEquals(Assert.java:118)
at org.testng.Assert.assertEquals(Assert.java:453)
at org.testng.Assert.assertEquals(Assert.java:463)
at com.withTestNG.Test1.funcTest2(Test1.java:17)
at sun.reflect.NativeMethodAccessorImpl.invoke0(Native Method)
at sun.reflect.NativeMethodAccessorImpl.invoke(NativeMethodAccessorImpl.java:62)
at sun.reflect.DelegatingMethodAccessorImpl.invoke(DelegatingMethodAccessorImpl.java:43)
at java.lang.reflect.Method.invoke(Method.java:498)
at org.testng.internal.MethodInvocationHelper.invokeMethod(MethodInvocationHelper.java:124)
at org.testng.internal.Invoker.invokeMethod(Invoker.java:583)
at org.testng.internal.Invoker.invokeTestMethod(Invoker.java:719)
at org.testng.internal.Invoker.invokeTestMethods(Invoker.java:989)
at org.testng.internal.TestMethodWorker.invokeTestMethods(TestMethodWorker.java:125)
at org.testng.internal.TestMethodWorker.run(TestMethodWorker.java:109)
at org.testng.TestRunner.privateRun(TestRunner.java:648)
at org.testng.TestRunner.run(TestRunner.java:505)
at org.testng.SuiteRunner.runTest(SuiteRunner.java:455)
at org.testng.SuiteRunner.runSequentially(SuiteRunner.java:450)
at org.testng.SuiteRunner.privateRun(SuiteRunner.java:415)
at org.testng.SuiteRunner.run(SuiteRunner.java:364)
at org.testng.SuiteRunnerWorker.runSuite(SuiteRunnerWorker.java:52)
at org.testng.SuiteRunnerWorker.run(SuiteRunnerWorker.java:84)
at org.testng.TestNG.runSuitesSequentially(TestNG.java:1208)
at org.testng.TestNG.runSuitesLocally(TestNG.java:1137)
at org.testng.TestNG.runSuites(TestNG.java:1049)
at org.testng.TestNG.run(TestNG.java:1017)
at org.testng.remote.AbstractRemoteTestNG.run(AbstractRemoteTestNG.java:114)
at org.testng.remote.RemoteTestNG.initAndRun(RemoteTestNG.java:251)
at org.testng.remote.RemoteTestNG.main(RemoteTestNG.java:77)
]]>
            </full-stacktrace>
          </exception> <!-- java.lang.AssertionError -->
          <reporter-output>
          </reporter-output>
        </test-method> <!-- funcTest2 -->
        <test-method status="PASS" signature="getResult(org.testng.ITestResult)[pri:0, instance:com.withTestNG.Test1@528931cf]" name="getResult" is-config="true" duration-ms="8" started-at="2019-02-03T13:37:21Z" finished-at="2019-02-03T13:37:21Z">
          <params>
            <param index="0">
              <value>
                <![CDATA[[TestResult name=funcTest2 status=FAILURE method=Test1.funcTest2()[pri:0, instance:com.withTestNG.Test1@528931cf] output={null}]]]>
              </value>
            </param>
          </params>
          <reporter-output>
          </reporter-output>
        </test-method> <!-- getResult -->
        <test-method status="FAIL" signature="funcTest3()[pri:0, instance:com.withTestNG.Test1@528931cf]" name="funcTest3" duration-ms="2" started-at="2019-02-03T13:37:21Z" finished-at="2019-02-03T13:37:21Z">
          <exception class="java.lang.AssertionError">
            <message>
              <![CDATA[null]]>
            </message>
            <full-stacktrace>
              <![CDATA[java.lang.AssertionError: null
at org.testng.Assert.fail(Assert.java:96)
at org.testng.Assert.assertNotEquals(Assert.java:1157)
at org.testng.Assert.assertNotEquals(Assert.java:1162)
at com.withTestNG.Test1.funcTest3(Test1.java:25)
at sun.reflect.NativeMethodAccessorImpl.invoke0(Native Method)
at sun.reflect.NativeMethodAccessorImpl.invoke(NativeMethodAccessorImpl.java:62)
at sun.reflect.DelegatingMethodAccessorImpl.invoke(DelegatingMethodAccessorImpl.java:43)
at java.lang.reflect.Method.invoke(Method.java:498)
at org.testng.internal.MethodInvocationHelper.invokeMethod(MethodInvocationHelper.java:124)
at org.testng.internal.Invoker.invokeMethod(Invoker.java:583)
at org.testng.internal.Invoker.invokeTestMethod(Invoker.java:719)
at org.testng.internal.Invoker.invokeTestMethods(Invoker.java:989)
at org.testng.internal.TestMethodWorker.invokeTestMethods(TestMethodWorker.java:125)
at org.testng.internal.TestMethodWorker.run(TestMethodWorker.java:109)
at org.testng.TestRunner.privateRun(TestRunner.java:648)
at org.testng.TestRunner.run(TestRunner.java:505)
at org.testng.SuiteRunner.runTest(SuiteRunner.java:455)
at org.testng.SuiteRunner.runSequentially(SuiteRunner.java:450)
at org.testng.SuiteRunner.privateRun(SuiteRunner.java:415)
at org.testng.SuiteRunner.run(SuiteRunner.java:364)
at org.testng.SuiteRunnerWorker.runSuite(SuiteRunnerWorker.java:52)
at org.testng.SuiteRunnerWorker.run(SuiteRunnerWorker.java:84)
at org.testng.TestNG.runSuitesSequentially(TestNG.java:1208)
at org.testng.TestNG.runSuitesLocally(TestNG.java:1137)
at org.testng.TestNG.runSuites(TestNG.java:1049)
at org.testng.TestNG.run(TestNG.java:1017)
at org.testng.remote.AbstractRemoteTestNG.run(AbstractRemoteTestNG.java:114)
at org.testng.remote.RemoteTestNG.initAndRun(RemoteTestNG.java:251)
at org.testng.remote.RemoteTestNG.main(RemoteTestNG.java:77)
]]>
            </full-stacktrace>
          </exception> <!-- java.lang.AssertionError -->
          <reporter-output>
          </reporter-output>
        </test-method> <!-- funcTest3 -->
        <test-method status="PASS" signature="getResult(org.testng.ITestResult)[pri:0, instance:com.withTestNG.Test1@528931cf]" name="getResult" is-config="true" duration-ms="2" started-at="2019-02-03T13:37:21Z" finished-at="2019-02-03T13:37:21Z">
          <params>
            <param index="0">
              <value>
                <![CDATA[[TestResult name=funcTest3 status=FAILURE method=Test1.funcTest3()[pri:0, instance:com.withTestNG.Test1@528931cf] output={null}]]]>
              </value>
            </param>
          </params>
          <reporter-output>
          </reporter-output>
        </test-method> <!-- getResult -->
        <test-method status="PASS" signature="tearDown()[pri:0, instance:com.withTestNG.Test1@528931cf]" name="tearDown" is-config="true" duration-ms="431" started-at="2019-02-03T13:37:21Z" finished-at="2019-02-03T13:37:21Z">
          <reporter-output>
          </reporter-output>
        </test-method> <!-- tearDown -->
      </class> <!-- com.withTestNG.Test1 -->
      <class name="com.withTestNG.Test2">
        <test-method status="PASS" signature="func2Test1()[pri:0, instance:com.withTestNG.Test2@ea1a8d5]" name="func2Test1" duration-ms="1" started-at="2019-02-03T13:37:21Z" finished-at="2019-02-03T13:37:21Z">
          <reporter-output>
          </reporter-output>
        </test-method> <!-- func2Test1 -->
        <test-method status="FAIL" signature="func2Test2()[pri:0, instance:com.withTestNG.Test2@ea1a8d5]" name="func2Test2" duration-ms="2" started-at="2019-02-03T13:37:21Z" finished-at="2019-02-03T13:37:21Z">
          <exception class="java.lang.AssertionError">
            <message>
              <![CDATA[expected [Yogi] but found [Yogesh]]]>
            </message>
            <full-stacktrace>
              <![CDATA[java.lang.AssertionError: expected [Yogi] but found [Yogesh]
at org.testng.Assert.fail(Assert.java:96)
at org.testng.Assert.failNotEquals(Assert.java:776)
at org.testng.Assert.assertEqualsImpl(Assert.java:137)
at org.testng.Assert.assertEquals(Assert.java:118)
at org.testng.Assert.assertEquals(Assert.java:453)
at org.testng.Assert.assertEquals(Assert.java:463)
at com.withTestNG.Test2.func2Test2(Test2.java:17)
at sun.reflect.NativeMethodAccessorImpl.invoke0(Native Method)
at sun.reflect.NativeMethodAccessorImpl.invoke(NativeMethodAccessorImpl.java:62)
at sun.reflect.DelegatingMethodAccessorImpl.invoke(DelegatingMethodAccessorImpl.java:43)
at java.lang.reflect.Method.invoke(Method.java:498)
at org.testng.internal.MethodInvocationHelper.invokeMethod(MethodInvocationHelper.java:124)
at org.testng.internal.Invoker.invokeMethod(Invoker.java:583)
at org.testng.internal.Invoker.invokeTestMethod(Invoker.java:719)
at org.testng.internal.Invoker.invokeTestMethods(Invoker.java:989)
at org.testng.internal.TestMethodWorker.invokeTestMethods(TestMethodWorker.java:125)
at org.testng.internal.TestMethodWorker.run(TestMethodWorker.java:109)
at org.testng.TestRunner.privateRun(TestRunner.java:648)
at org.testng.TestRunner.run(TestRunner.java:505)
at org.testng.SuiteRunner.runTest(SuiteRunner.java:455)
at org.testng.SuiteRunner.runSequentially(SuiteRunner.java:450)
at org.testng.SuiteRunner.privateRun(SuiteRunner.java:415)
at org.testng.SuiteRunner.run(SuiteRunner.java:364)
at org.testng.SuiteRunnerWorker.runSuite(SuiteRunnerWorker.java:52)
at org.testng.SuiteRunnerWorker.run(SuiteRunnerWorker.java:84)
at org.testng.TestNG.runSuitesSequentially(TestNG.java:1208)
at org.testng.TestNG.runSuitesLocally(TestNG.java:1137)
at org.testng.TestNG.runSuites(TestNG.java:1049)
at org.testng.TestNG.run(TestNG.java:1017)
at org.testng.remote.AbstractRemoteTestNG.run(AbstractRemoteTestNG.java:114)
at org.testng.remote.RemoteTestNG.initAndRun(RemoteTestNG.java:251)
at org.testng.remote.RemoteTestNG.main(RemoteTestNG.java:77)
]]>
            </full-stacktrace>
          </exception> <!-- java.lang.AssertionError -->
          <reporter-output>
          </reporter-output>
        </test-method> <!-- func2Test2 -->
        <test-method status="PASS" signature="getResult(org.testng.ITestResult)[pri:0, instance:com.withTestNG.Test2@ea1a8d5]" name="getResult" is-config="true" duration-ms="0" started-at="2019-02-03T13:37:21Z" finished-at="2019-02-03T13:37:21Z">
          <params>
            <param index="0">
              <value>
                <![CDATA[[TestResult name=func2Test1 status=SUCCESS method=Test2.func2Test1()[pri:0, instance:com.withTestNG.Test2@ea1a8d5] output={null}]]]>
              </value>
            </param>
          </params>
          <reporter-output>
          </reporter-output>
        </test-method> <!-- getResult -->
        <test-method status="PASS" signature="getResult(org.testng.ITestResult)[pri:0, instance:com.withTestNG.Test2@ea1a8d5]" name="getResult" is-config="true" duration-ms="3" started-at="2019-02-03T13:37:21Z" finished-at="2019-02-03T13:37:21Z">
          <params>
            <param index="0">
              <value>
                <![CDATA[[TestResult name=func2Test2 status=FAILURE method=Test2.func2Test2()[pri:0, instance:com.withTestNG.Test2@ea1a8d5] output={null}]]]>
              </value>
            </param>
          </params>
          <reporter-output>
          </reporter-output>
        </test-method> <!-- getResult -->
        <test-method status="FAIL" signature="func2Test3()[pri:0, instance:com.withTestNG.Test2@ea1a8d5]" name="func2Test3" duration-ms="3" started-at="2019-02-03T13:37:21Z" finished-at="2019-02-03T13:37:21Z">
          <exception class="java.lang.AssertionError">
            <message>
              <![CDATA[null]]>
            </message>
            <full-stacktrace>
              <![CDATA[java.lang.AssertionError: null
at org.testng.Assert.fail(Assert.java:96)
at org.testng.Assert.assertNotEquals(Assert.java:1157)
at org.testng.Assert.assertNotEquals(Assert.java:1162)
at com.withTestNG.Test2.func2Test3(Test2.java:25)
at sun.reflect.NativeMethodAccessorImpl.invoke0(Native Method)
at sun.reflect.NativeMethodAccessorImpl.invoke(NativeMethodAccessorImpl.java:62)
at sun.reflect.DelegatingMethodAccessorImpl.invoke(DelegatingMethodAccessorImpl.java:43)
at java.lang.reflect.Method.invoke(Method.java:498)
at org.testng.internal.MethodInvocationHelper.invokeMethod(MethodInvocationHelper.java:124)
at org.testng.internal.Invoker.invokeMethod(Invoker.java:583)
at org.testng.internal.Invoker.invokeTestMethod(Invoker.java:719)
at org.testng.internal.Invoker.invokeTestMethods(Invoker.java:989)
at org.testng.internal.TestMethodWorker.invokeTestMethods(TestMethodWorker.java:125)
at org.testng.internal.TestMethodWorker.run(TestMethodWorker.java:109)
at org.testng.TestRunner.privateRun(TestRunner.java:648)
at org.testng.TestRunner.run(TestRunner.java:505)
at org.testng.SuiteRunner.runTest(SuiteRunner.java:455)
at org.testng.SuiteRunner.runSequentially(SuiteRunner.java:450)
at org.testng.SuiteRunner.privateRun(SuiteRunner.java:415)
at org.testng.SuiteRunner.run(SuiteRunner.java:364)
at org.testng.SuiteRunnerWorker.runSuite(SuiteRunnerWorker.java:52)
at org.testng.SuiteRunnerWorker.run(SuiteRunnerWorker.java:84)
at org.testng.TestNG.runSuitesSequentially(TestNG.java:1208)
at org.testng.TestNG.runSuitesLocally(TestNG.java:1137)
at org.testng.TestNG.runSuites(TestNG.java:1049)
at org.testng.TestNG.run(TestNG.java:1017)
at org.testng.remote.AbstractRemoteTestNG.run(AbstractRemoteTestNG.java:114)
at org.testng.remote.RemoteTestNG.initAndRun(RemoteTestNG.java:251)
at org.testng.remote.RemoteTestNG.main(RemoteTestNG.java:77)
]]>
            </full-stacktrace>
          </exception> <!-- java.lang.AssertionError -->
          <reporter-output>
          </reporter-output>
        </test-method> <!-- func2Test3 -->
        <test-method status="PASS" signature="getResult(org.testng.ITestResult)[pri:0, instance:com.withTestNG.Test2@ea1a8d5]" name="getResult" is-config="true" duration-ms="2" started-at="2019-02-03T13:37:21Z" finished-at="2019-02-03T13:37:21Z">
          <params>
            <param index="0">
              <value>
                <![CDATA[[TestResult name=func2Test3 status=FAILURE method=Test2.func2Test3()[pri:0, instance:com.withTestNG.Test2@ea1a8d5] output={null}]]]>
              </value>
            </param>
          </params>
          <reporter-output>
          </reporter-output>
        </test-method> <!-- getResult -->
      </class> <!-- com.withTestNG.Test2 -->
    </test> <!-- Test -->
  </suite> <!-- Suite -->
</testng-results>
